Workbook

Sheet 封面
C1: 文件类型 | D1: 记录 | E1: 文件编号
C2: 密 级 | D2: □绝密 □机密 ■秘密 | E2: 适用范围 | F2: 质量体系
B11: Onemap产品库出品验收报告
B21: 生效日期 | E21: 版本号 | F21: V1.0
B22: 版本状态 | C22: □草案 □定稿 ■发布版 □修订稿
B23: 编 制 人 | C23: 王乾 | E23: 编制日期 | F23: 45107
B24: 审 核 人 | C24: 魏娜 | E24: 审核日期 | F24: 45107
B25: 批 准 人 | C25: 魏娜 | E25: 批准日期 | F25: 45107

Sheet 修订履历
C1: 文件类型 | D1: 标准 | E1: 文件编号
C2: 密 级 | D2: □绝密 □机密 ■秘密 | E2: 适用范围 | F2: 质量体系
A3: Document Revision 修订履历
A5: Version 版本 | B5: Date 日期 | C5: Changes 修订内容 | D5: Remarks 备注 | E5: Author 作者 | F5: 审核人 | G5: 批准人
A6: V1.0 | B6: 45107 | C6: 初稿 | D6: \ | E6: 王乾 | F6: 魏娜 | G6: 魏娜

Sheet 综述
A1: 1、实施记录
A2: 验收城市 | B2: 25个城市
A3: 验收版本号 | B3: LG_OneMap_20230630_V1
A4: 验收里程 | B4: 1311.2（km）
A5: 验收时间 | B5: 45107
A6: 验收人员 | B6: 王乾
A7: 验收结论 | B7: 通过
A10: 序号 | B10: 检查大类 | C10: 检查项数量 | D10: 合格项数量 | E10: 不合格项数量 | F10: 说明
A11: 1 | B11: 文件列表检查 | C11: 4 | D11: 4 | E11: 0 | F11: 检查文件夹及里面图层完整性，目前情况：编译暂未上线图层2个，不支持图层2个，部分支持图层1个（未做质量保证），产品不转出图层6个，内容为空图层2个
A12: 2 | B12: 提交范围检查 | C12: 1 | D12: 1 | E12: 0 | F12: 现状按照任务范围框判断数据有无。
A13: 3 | B13: 规格+值域+主外键 | C13: 233 | D13: 233 | E13: 0
A14: 4 | B14: 几何拓扑逻辑检查 | C14: 126 | D14: =C14-E14 -> 126 | E14: 0
A15: 5 | B15: 与现实世界一致性检查 | C15: 50 | D15: =C15-E15 -> 48 | E15: 2 | F15: 2项A为停止线工艺变更（取消虚拟停止线），非高速重点要素，不影响智能驾驶领航功能，后续刷库改善
A20: 3、图表展示
A39: 4、说明
A40: 1）质量标准:量产
A41: 检查项等级 | B41: 质量标准
A42: S | B42: 1
A43: A | B43: 0.9984
A44: B | B44: 0.99
A45: C | B45: 0.98
A47: 2）公式说明
A48: 人工正确率=1-错误量/(验收数量+遗漏-冗余）*100%

Sheet 1.文件列表检查
A1: 序号 | B1: 检查项代码 | C1: 大类检查项 | D1: 中类检查项 | E1: 小类检查项 | F1: 检查项等级 | G1: 质量标准 | H1: 检查方法 | I1: 检查比例 | J1: 验收数量 | K1: 错误量 | L1: 正确率 | M1: 是否合格 | N1: 备注
A2: 1 | B2: 111001 | C2: Filelist | D2: 唯一性 | E2: 名称唯一 | F2: S | G2: 1 | H2: 人工 | I2: 抽检 | J2: =31*25 -> 775 | K2: 0 | L2: =1-K2/J2 -> 1 | M2: 是
A3: 2 | B3: 111002 | C3: Filelist | D3: 完备性 | E3: 文件夹存在完备 | F3: S | G3: 1 | H3: 人工 | I3: 抽检 | J3: 25 | K3: 0 | L3: =1-K3/J3 -> 1 | M3: 是
A4: 3 | B4: 111003 | C4: Filelist | D4: 正确性 | E4: 文件格式正确 | F4: S | G4: 1 | H4: 人工 | I4: 抽检 | J4: =31*25 -> 775 | K4: 0 | L4: =1-K4/J4 -> 1 | M4: 是
A5: 4 | B5: 111004 | C5: Filelist | D5: 正确性 | E5: 文件数量正确 | F5: S | G5: 1 | H5: 人工 | I5: 抽检 | J5: =31*25 -> 775 | K5: 0 | L5: =1-K5/J5 -> 1 | M5: 是

Sheet 2.提交范围检查
A1: 序号 | B1: 检查项代码 | C1: 大类检查项 | D1: 中类检查项 | E1: 小类检查项 | F1: 检查项等级 | G1: 质量标准 | H1: 检查方法 | I1: 检查比例 | J1: 验收数量 | K1: 错误量 | L1: 正确率 | M1: 是否合格 | N1: 备注
A2: 1 | B2: WZX000001 | C2: Lane | D2: GEOMETRY | E2: Lane::GEOMETRY完整性检查 | F2: S | G2: 1 | H2: 人工 | I2: 抽检 | J2: 40952 | K2: 0 | L2: =1-K2/J2 -> 1 | M2: =IF(L2>=G2,"是",“否”) -> 是

Sheet 3.规格+值域+主外键
A1: 序号 | B1: 检查项代码 | C1: 检查表名 | D1: 检查字段名 | E1: 检查内容 | F1: 检查项等级 | G1: 质量标准 | H1: 检查方法 | I1: 检查比例 | J1: 验收数量 | K1: 错误量 | L1: 正确率 | M1: 是否合格 | N1: 备注
A2: 1 | B2: 10001 | C2: lgmap_lane | D2: geometry | E2: 字段定义检查 | F2: S | G2: 1 | H2: 工具 | I2: 1 | J2: =VLOOKUP(C:C,'4.几何拓扑逻辑检查'!D:J,7,FALSE) -> 39625 | K2: 0 | L2: =1-K2/J2 -> 1 | M2: =IF(L2>=I2,"是","否") -> 是
A3: 2 | B3: 10002 | C3: lgmap_lane | D3: left_divider_id | E3: 字段定义检查 | F3: S | G3: 1 | H3: 工具 | I3: 1 | J3: =VLOOKUP(C:C,'4.几何拓扑逻辑检查'!D:J,7,FALSE) -> 39625 | K3: 0 | L3: =1-K3/J3 -> 1 | M3: =IF(L3>=I3,"是","否") -> 是
A4: 3 | B4: 10003 | C4: lgmap_lane | D4: right_divider_id | E4: 字段定义检查 | F4: S | G4: 1 | H4: 工具 | I4: 1 | J4: =VLOOKUP(C:C,'4.几何拓扑逻辑检查'!D:J,7,FALSE) -> 39625 | K4: 0 | L4: =1-K4/J4 -> 1 | M4: =IF(L4>=I4,"是","否") -> 是
A5: 4 | B5: 10004 | C5: lgmap_lane | D5: left_chg_lane_id | E5: 字段定义检查 | F5: S | G5: 1 | H5: 工具 | I5: 1 | J5: =VLOOKUP(C:C,'4.几何拓扑逻辑检查'!D:J,7,FALSE) -> 39625 | K5: 0 | L5: =1-K5/J5 -> 1 | M5: =IF(L5>=I5,"是","否") -> 是
A6: 5 | B6: 10005 | C6: lgmap_lane | D6: right_chg_lane_id | E6: 字段定义检查 | F6: S | G6: 1 | H6: 工具 | I6: 1 | J6: =VLOOKUP(C:C,'4.几何拓扑逻辑检查'!D:J,7,FALSE) -> 39625 | K6: 0 | L6: =1-K6/J6 -> 1 | M6: =IF(L6>=I6,"是","否") -> 是
A7: 6 | B7: 10006 | C7: lgmap_lane | D7: lane_topo_direction | E7: 字段定义检查 | F7: S | G7: 1 | H7: 工具 | I7: 1 | J7: =VLOOKUP(C:C,'4.几何拓扑逻辑检查'!D:J,7,FALSE) -> 39625 | K7: 0 | L7: =1-K7/J7 -> 1 | M7: =IF(L7>=I7,"是","否") -> 是
A8: 7 | B8: 10007 | C8: lgmap_lane | D8: length | E8: 字段定义检查 | F8: S | G8: 1 | H8: 工具 | I8: 1 | J8: =VLOOKUP(C:C,'4.几何拓扑逻辑检查'!D:J,7,FALSE) -> 39625 | K8: 0 | L8: =1-K8/J8 -> 1 | M8: =IF(L8>=I8,"是","否") -> 是
A9: 8 | B9: 10008 | C9: lgmap_lane | D9: reverse_flag | E9: 字段定义检查 | F9: S | G9: 1 | H9: 工具 | I9: 1 | J9: =VLOOKUP(C:C,'4.几何拓扑逻辑检查'!D:J,7,FALSE) -> 39625 | K9: 0 | L9: =1-K9/J9 -> 1 | M9: =IF(L9>=I9,"是","否") -> 是
A10: 9 | B10: 10009 | C10: lgmap_lane | D10: reverse_lane_id | E10: 字段定义检查 | F10: S | G10: 1 | H10: 工具 | I10: 1 | J10: =VLOOKUP(C:C,'4.几何拓扑逻辑检查'!D:J,7,FALSE) -> 39625 | K10: 0 | L10: =1-K10/J10 -> 1 | M10: =IF(L10>=I10,"是","否") -> 是
A11: 10 | B11: 10011 | C11: lgmap_lane | D11: category_main | E11: 字段定义检查 | F11: S | G11: 1 | H11: 工具 | I11: 1 | J11: =VLOOKUP(C:C,'4.几何拓扑逻辑检查'!D:J,7,FALSE) -> 39625 | K11: 0 | L11: =1-K11/J11 -> 1 | M11: =IF(L11>=I11,"是","否") -> 是
A12: 11 | B12: 10012 | C12: lgmap_lane | D12: category_location | E12: 字段定义检查 | F12: S | G12: 1 | H12: 工具 | I12: 1 | J12: =VLOOKUP(C:C,'4.几何拓扑逻辑检查'!D:J,7,FALSE) -> 39625 | K12: 0 | L12: =1-K12/J12 -> 1 | M12: =IF(L12>=I12,"是","否") -> 是
A13: 12 | B13: 10013 | C13: lgmap_lane | D13: category_vehicle | E13: 字段定义检查 | F13: S | G13: 1 | H13: 工具 | I13: 1 | J13: =VLOOKUP(C:C,'4.几何拓扑逻辑检查'!D:J,7,FALSE) -> 39625 | K13: 0 | L13: =1-K13/J13 -> 1 | M13: =IF(L13>=I13,"是","否") -> 是
... A32: 31 | B32: 10051 | C32: lgmap_lane_divider | D32: adcity_code | E32: 字段定义检查 | F32: S | G32: 1 | H32: 工具 | I32: 1 | J32: =VLOOKUP(C:C,'4.几何拓扑逻辑检查'!D:J,7,FALSE) -> 55050 | K32: 0 | L32: =1-K32/J32 -> 1 | M32: =IF(L32>=I32,"是","否") -> 是
A33: 32 | B33: 10052 | C33: lgmap_divider_road_form | D33: divider_id | E33: 字段定义检查 | F33: S | G33: 1 | H33: 工具 | I33: 1 | J33: 14435 | K33: 0 | L33: =1-K33/J33 -> 1 | M33: =IF(L33>=I33,"是","否") -> 是
A34: 33 | B34: 10053 | C34: lgmap_divider_road_form | D34: kind | E34: 字段定义检查 | F34: S | G34: 1 | H34: 工具 | I34: 1 | J34: 14435 | K34: 0 | L34: =1-K34/J34 -> 1 | M34: =IF(L34>=I34,"是","否") -> 是
A35: 34 | B35: 10054 | C35: lgmap_divider_road_form | D35: muti_digitized | E35: 字段定义检查 | F35: S | G35: 1 | H35: 工具 | I35: 1 | J35: 14435 | K35: 0 | L35: =1-K35/J35 -> 1 | M35: =IF(L35>=I35,"是","否") -> 是
A36: 35 | B36: 10056 | C36: lgmap_divider_road_form | D36: adcity_code | E36: 字段定义检查 | F36: S | G36: 1 | H36: 工具 | I36: 1 | J36: 14435 | K36: 0 | L36: =1-K36/J36 -> 1 | M36: =IF(L36>=I36,"是","否") -> 是
A37: 36 | B37: 10057 | C37: lgmap_lane_top | D37: in_lane_id | E37: 字段定义检查 | F37: S | G37: 1 | H37: 工具 | I37: 1 | J37: =VLOOKUP(C:C,'4.几何拓扑逻辑检查'!D:J,7,FALSE) -> 38442 | K37: 0 | L37: =1-K37/J37 -> 1 | M37: =IF(L37>=I37,"是","否") -> 是
A38: 37 | B38: 10058 | C38: lgmap_lane_top | D38: out_lane_id | E38: 字段定义检查 | F38: S | G38: 1 | H38: 工具 | I38: 1 | J38: =VLOOKUP(C:C,'4.几何拓扑逻辑检查'!D:J,7,FALSE) -> 38442 | K38: 0 | L38: =1-K38/J38 -> 1 | M38: =IF(L38>=I38,"是","否") -> 是
A39: 38 | B39: 10059 | C39: lgmap_lane_top | D39: top_dir | E39: 字段定义检查 | F39: S | G39: 1 | H39: 工具 | I39: 1 | J39: =VLOOKUP(C:C,'4.几何拓扑逻辑检查'!D:J,7,FALSE) -> 38442 | K39: 0 | L39: =1-K39/J39 -> 1 | M39: =IF(L39>=I39,"是","否") -> 是
A40: 39 | B40: 10060 | C40: lgmap_lane_top | D40: cross_type | E40: 字段定义检查 | F40: S | G40: 1 | H40: 工具 | I40: 1 | J40: =VLOOKUP(C:C,'4.几何拓扑逻辑检查'!D:J,7,FALSE) -> 38442 | K40: 0 | L40: =1-K40/J40 -> 1 | M40: =IF(L40>=I40,"是","否") -> 是
A41: 40 | B41: 10061 | C41: lgmap_lane_top | D41: adcity_code | E41: 字段定义检查 | F41: S | G41: 1 | H41: 工具 | I41: 1 | J41: =VLOOKUP(C:C,'4.几何拓扑逻辑检查'!D:J,7,FALSE) -> 38442 | K41: 0 | L41: =1-K41/J41 -> 1 | M41: =IF(L41>=I41,"是","否") -> 是
A42: 41 | B42: 10062 | C42: lgmap_junction | D42: geometry | E42: 字段定义检查 | F42: S | G42: 1 | H42: 工具 | I42: 1 | J42: =VLOOKUP(C:C,'4.几何拓扑逻辑检查'!D:J,7,FALSE) -> 1872 | K42: 0 | L42: =1-K42/J42 -> 1 | M42: =IF(L42>=I42,"是","否") -> 是
A43: 42 | B43: 10063 | C43: lgmap_junction | D43: lane_list | E43: 字段定义检查 | F43: S | G43: 1 | H43: 工具 | I43: 1 | J43: =VLOOKUP(C:C,'4.几何拓扑逻辑检查'!D:J,7,FALSE) -> 1872 | K43: 0 | L43: =1-K43/J43 -> 1 | M43: =IF(L43>=I43,"是","否") -> 是
A44: 43 | B44: 10064 | C44: lgmap_junction | D44: type | E44: 字段定义检查 | F44: S | G44: 1 | H44: 工具 | I44: 1 | J44: =VLOOKUP(C:C,'4.几何拓扑逻辑检查'!D:J,7,FALSE) -> 1872 | K44: 0 | L44: =1-K44/J44 -> 1 | M44: =IF(L44>=I44,"是","否") -> 是
A45: 44 | B45: 10065 | C45: lgmap_junction | D45: adcity_code | E45: 字段定义检查 | F45: S | G45: 1 | H45: 工具 | I45: 1 | J45: =VLOOKUP(C:C,'4.几何拓扑逻辑检查'!D:J,7,FALSE) -> 1872 | K45: 0 | L45: =1-K45/J45 -> 1 | M45: =IF(L45>=I45,"是","否") -> 是
A46: 45 | B46: 10073 | C46: lgmap_lane_speed_general | D46: divider_id | E46: 字段定义检查 | F46: S | G46: 1 | H46: 工具 | I46: 1 | J46: =VLOOKUP(C:C,'4.几何拓扑逻辑检查'!D:J,7,FALSE) -> 39676 | K46: 0 | L46: =1-K46/J46 -> 1 | M46: =IF(L46>=I46,"是","否") -> 是
A47: 46 | B47: 10074 | C47: lgmap_lane_speed_general | D47: lane_id | E47: 字段定义检查 | F47: S | G47: 1 | H47: 工具 | I47: 1 | J47: =VLOOKUP(C:C,'4.几何拓扑逻辑检查'!D:J,7,FALSE) -> 39676 | K47: 0 | L47: =1-K47/J47 -> 1 | M47: =IF(L47>=I47,"是","否") -> 是
A48: 47 | B48: 10075 | C48: lgmap_lane_speed_general | D48: lane_dir | E48: 字段定义检查 | F48: S | G48: 1 | H48: 工具 | I48: 1 | J48: =VLOOKUP(C:C,'4.几何拓扑逻辑检查'!D:J,7,FALSE) -> 39676 | K48: 0 | L48: =1-K48/J48 -> 1 | M48: =IF(L48>=I48,"是","否") -> 是
... A53: 52 | B53: 10081 | C53: lgmap_lane_speed_general | D53: adcity_code | E53: 字段定义检查 | F53: S | G53: 1 | H53: 工具 | I53: 1 | J53: =VLOOKUP(C:C,'4.几何拓扑逻辑检查'!D:J,7,FALSE) -> 39676 | K53: 0 | L53: =1-K53/J53 -> 1 | M53: =IF(L53>=I53,"是","否") -> 是
A54: 53 | B54: 10096 | C54: lgmap_object_line_roadsurface | D54: geometry | E54: 字段定义检查 | F54: S | G54: 1 | H54: 工具 | I54: 1 | J54: 38 | K54: 0 | L54: =1-K54/J54 -> 1 | M54: =IF(L54>=I54,"是","否") -> 是
A55: 54 | B55: 10097 | C55: lgmap_object_line_roadsurface | D55: type | E55: 字段定义检查 | F55: S | G55: 1 | H55: 工具 | I55: 1 | J55: 38 | K55: 0 | L55: =1-K55/J55 -> 1 | M55: =IF(L55>=I55,"是","否") -> 是
A56: 55 | B56: 10098 | C56: lgmap_object_line_roadsurface | D56: adcity_code | E56: 字段定义检查 | F56: S | G56: 1 | H56: 工具 | I56: 1 | J56: 38 | K56: 0 | L56: =1-K56/J56 -> 1 | M56: =IF(L56>=I56,"是","否") -> 是
A57: 56 | B57: 10099 | C57: lgmap_object_line_pole | D57: geometry | E57: 字段定义检查 | F57: S | G57: 1 | H57: 工具 | I57: 1 | J57: =VLOOKUP(C:C,'4.几何拓扑逻辑检查'!D:J,7,FALSE) -> 17737 | K57: 0 | L57: =1-K57/J57 -> 1 | M57: =IF(L57>=I57,"是","否") -> 是
A58: 57 | B58: 10100 | C58: lgmap_object_line_pole | D58: type | E58: 字段定义检查 | F58: S | G58: 1 | H58: 工具 | I58: 1 | J58: =VLOOKUP(C:C,'4.几何拓扑逻辑检查'!D:J,7,FALSE) -> 17737 | K58: 0 | L58: =1-K58/J58 -> 1 | M58: =IF(L58>=I58,"是","否") -> 是
A59: 58 | B59: 10101 | C59: lgmap_object_line_pole | D59: adcity_code | E59: 字段定义检查 | F59: S | G59: 1 | H59: 工具 | I59: 1 | J59: =VLOOKUP(C:C,'4.几何拓扑逻辑检查'!D:J,7,FALSE) -> 17737 | K59: 0 | L59: =1-K59/J59 -> 1 | M59: =IF(L59>=I59,"是","否") -> 是
A60: 59 | B60: 10102 | C60: lgmap_object_physical_boundary | D60: geometry | E60: 字段定义检查 | F60: S | G60: 1 | H60: 工具 | I60: 1 | J60: =VLOOKUP(C:C,'4.几何拓扑逻辑检查'!D:J,7,FALSE) -> 36039 | K60: 0 | L60: =1-K60/J60 -> 1 | M60: =IF(L60>=I60,"是","否") -> 是
A61: 60 | B61: 10103 | C61: lgmap_object_physical_boundary | D61: type | E61: 字段定义检查 | F61: S | G61: 1 | H61: 工具 | I61: 1 | J61: =VLOOKUP(C:C,'4.几何拓扑逻辑检查'!D:J,7,FALSE) -> 36039 | K61: 0 | L61: =1-K61/J61 -> 1 | M61: =IF(L61>=I61,"是","否") -> 是
A62: 61 | B62: 10104 | C62: lgmap_object_physical_boundary | D62: divider_id | E62: 字段定义检查 | F62: S | G62: 1 | H62: 工具 | I62: 1 | J62: =VLOOKUP(C:C,'4.几何拓扑逻辑检查'!D:J,7,FALSE) -> 36039 | K62: 0 | L62: =1-K62/J62 -> 1 | M62: =IF(L62>=I62,"是","否") -> 是
...

Sheet 4.几何拓扑逻辑检查
A1: 序号 | B1: chk_id | C1: check_name | D1: 图层 | E1: 字段 | F1: 检查项等级 | G1: 标准正确率 | H1: 检查方法 | I1: 检查比例 | J1: 验收数量 | K1: 错误量 | L1: 正确率 | M1: 是否合格
A2: 1 | B2: HDMKLOGIC2602001 | C2: lgmap_Reference_line_top::from_line前后继拓扑检查 | D2: lgmap_Reference_line_top | E2: from_line | F2: C | G2: 0.98 | H2: 工具 | I2: 1 | J2: 13088 | K2: 0 | L2: 1 | M2: 是
A3: 2 | B3: HDMKLOGIC2710003 | C3: lgmap_road::direct道路方向合理性检查2 | D3: lgmap_road | E3: direct | F3: A | G3: 0.9984 | H3: 工具 | I3: 1 | J3: 14777 | K3: 0 | L3: 1 | M3: 是
A4: 3 | B4: HDMKLOGIC2702003 | C4: lgmap_road::geometry道路几何完备性检查3 | D4: lgmap_road | E4: geometry | F4: A | G4: 0.9984 | H4: 工具 | I4: 1 | J4: 14777 | K4: 3 | L4: 0.99979698 | M4: 是
A5: 4 | B5: HDMKLOGIC2702016 | C5: lgmap_road::geometry位置检查 | D5: lgmap_road | E5: geometry | F5: A | G5: 0.9984 | H5: 工具 | I5: 1 | J5: 14777 | K5: 10.983333 | L5: 0.99925673 | M5: 是
A6: 5 | B6: HDMKLOGIC2708014 | C6: lgmap_road::kind道路种别合理性检查13 | D6: lgmap_road | E6: kind | F6: B | G6: 0.99 | H6: 工具 | I6: 1 | J6: 14777 | K6: 0 | L6: 1 | M6: 是
A7: 6 | B7: HDMKLOGIC2708017 | C7: lgmap_road::kind道路种别合理性检查16 | D7: lgmap_road | E7: kind | F7: B | G7: 0.99 | H7: 工具 | I7: 1 | J7: 14777 | K7: 0 | L7: 1 | M7: 是
A8: 7 | B8: HDMKLOGIC2708008 | C8: lgmap_road::kind道路种别合理性检查6 | D8: lgmap_road | E8: kind | F8: B | G8: 0.99 | H8: 工具 | I8: 1 | J8: 14777 | K8: 91.785714 | L8: 0.99378861 | M8: 是
A9: 8 | B9: HDMKLOGIC2711014 | C9: lgmap_road::lane_num车道数合理性检查2 | D9: lgmap_road | E9: lane_num | F9: B | G9: 0.99 | H9: 工具 | I9: 1 | J9: 14777 | K9: 60.506024 | L9: 0.99590539 | M9: 是
A10: 9 | B10: HDMKLOGIC2711010 | C10: lgmap_road::lane_num道路总车道数检查 | D10: lgmap_road | E10: lane_num | F10: B | G10: 0.99 | H10: 工具 | I10: 1 | J10: 14777 | K10: 0 | L10: 1 | M10: 是
A11: 10 | B11: HDMKLOGIC2802002 | C11: lgmap_road_node::geometryid编号在道路中不存在 | D11: lgmap_road_node | E11: geometry | F11: A | G11: 0.9984 | H11: 工具 | I11: 1 | J11: 14838 | K11: 17 | L11: 0.99885429 | M11: 是
A12: 11 | B12: HDMKLOGIC2802001 | C12: lgmap_road_node::geometry几何重复检查 | D12: lgmap_road_node | E12: geometry | F12: A | G12: 0.9984 | H12: 工具 | I12: 1 | J12: 14838 | K12: 19 | L12: 0.9987195 | M12: 是
A13: 12 | B13: HDMKLOGIC3802007 | C13: lgmap_road_section::geometry面内存在杆错误 | D13: lgmap_road_section | E13: geometry | F13: A | G13: 0.9984 | H13: 工具 | I13: 1 | J13: 13937 | K13: 7 | L13: 0.99949774 | M13: 是
A14: 13 | B14: 20048 | C14: 常规限速值为0时,来源非不应用报错；常规限速值非0时,来源为不应用报错。（一次质检报） | D14: lgmap_lane_speed_general | E14: max_speed_src/min_speed_src | F14: B | G14: 0.99 | H14: 工具 | I14: 1 | J14: 39676 | K14: 321 | L14: 0.99190947 | M14: 是
A15: 15 | B15: MKLOGIC0602010 | C15: 车道数变化区域的路口功能面正确性检查 | D15: lgmap_junction | E15: geometry | F15: C | G15: 0.98 | H15: 工具 | I15: 1 | J15: 1872 | K15: 0 | L15: 1 | M15: 是
A16: 16 | B16: HDMKLOGIC010632 | C16: 车道中心线的可右变同向车道ID正确性检查 | D16: lgmap_lane | E16: right_divider_id | F16: A | G16: 0.9984 | H16: 工具 | I16: 1 | J16: 39625 | K16: 0 | L16: 1 | M16: 是
A17: 17 | B17: HDMKLOGIC010531 | C17: 车道中心线的可左变同向车道ID正确性检查 | D17: lgmap_lane | E17: left_chg_lane_id | F17: A | G17: 0.9984 | H17: 工具 | I17: 1 | J17: 39625 | K17: 0 | L17: 1 | M17: 是
A18: 18 | B18: HDMKLOGIC0133044 | C18: 车道中心线的最大宽度正确性检查 | D18: lgmap_lane | E18: max_width | F18: B | G18: 0.99 | H18: 工具 | I18: 1 | J18: 39625 | K18: 0 | L18: 1 | M18: 是
A19: 19 | B19: MKLOGIC0102007 | C19: 车道中心线孤立检查 | D19: lgmap_lane | E19: geometry | F19: A | G19: 0.9984 | H19: 工具 | I19: 1 | J19: 39625 | K19: 0 | L19: 1 | M19: 是
A20: 20 | B20: HDMKLOGIC0316019 | C20: 车道中心线关联的左右边线长度不一致检查 | D20: lgmap_lane_divider | E20: geometry | F20: A | G20: 0.9984 | H20: 工具 | I20: 1 | J20: 55050 | K20: 0 | L20: 1 | M20: 是
A21: 21 | B21: HDMKLOGIC0505007 | C21: 车道中心线汇车类型制作正确性检查 | D21: lgmap_lane_top | E21: cross_type | F21: A | G21: 0.9984 | H21: 工具 | I21: 1 | J21: 38442 | K21: 13 | L21: =1-K21/J21 -> 0.99966183 | M21: 是
A22: 22 | B22: HDMKLOGIC0905007 | C22: 车道最高常规限速与交通标牌限速不一致检查 | D22: lgmap_lane_speed_general | E22: max_speed | F22: B | G22: 0.99 | H22: 工具 | I22: 1 | J22: 39676 | K22: 16 | L22: 0.99959673 | M22: 是
A23: 23 | B23: HDMKLOGIC0906001 | C23: 车道最高限速来源错误 | D23: lgmap_lane_speed_general | E23: max_speed_src | F23: B | G23: 0.99 | H23: 工具 | I23: 1 | J23: 39676 | K23: 67 | L23: 0.99831132 | M23: 是
A24: 24 | B24: HDMKLOGIC0303002 | C24: 导流区边线附加属性检查 | D24: lgmap_lane_divider | E24: additional_type | F24: B | G24: 0.99 | H24: 工具 | I24: 1 | J24: 55050 | K24: 0 | L24: 1 | M24: 是
A25: 25 | B25: MKLOGIC2204022 | C25: 导流区与中心线的建立关系正确性检查 | D25: lgmap_overlap | E25: object_id | F25: B | G25: 0.99 | H25: 工具 | I25: 1 | J25: 194834 | K25: 93.067797 | L25: 0.99952232 | M25: 是
A26: 26 | B26: MKLOGIC2204025 | C26: 导向箭头与中心线的建立关系正确性检查 | D26: lgmap_overlap | E26: object_id | F26: B | G26: 0.99 | H26: 工具 | I26: 1 | J26: 194834 | K26: 4 | L26: 0.99997947 | M26: 是
A27: 27 | B27: HDMKLOGIC1402016 | C27: 道路边界分隔线必须被物理隔离关联检查 | D27: lgmap_object_physical_boundary | E27: geometry | F27: B | G27: 0.99 | H27: 工具 | I27: 1 | J27: 36039 | K27: 2.4146341 | L27: 0.999933 | M27: 是
A28: 28 | B28: HDMKLOGIC0309007 | C28: 道路级车道类型同组赋值检查 | D28: lgmap_lane_divider | E28: category_location | F28: B | G28: 0.99 | H28: 工具 | I28: 1 | J28: 55050 | K28: 4 | L28: 0.99992734 | M28: 是
A29: 29 | B29: MKLOGIC2204021 | C29: 地面文字与中心线的建立关系正确性检查 | D29: lgmap_overlap | E29: object_id | F29: B | G29: 0.99 | H29: 工具 | I29: 1 | J29: 194834 | K29: 7 | L29: 0.99996407 | M29: 是
A30: 30 | B30: HDMKLOGIC1402014 | C30: 非虚拟物理隔离和分隔线打断检查 | D30: lgmap_object_physical_boundary | E30: geometry | F30: B | G30: 0.99 | H30: 工具 | I30: 1 | J30: 36039 | K30: 8.1971831 | L30: 0.99977255 | M30: 是
A31: 31 | B31: HDMKLOGIC0302010 | C31: 分隔线类型所在位置检查4 | D31: lgmap_lane_divider | E31: type | F31: B | G31: 0.99 | H31: 工具 | I31: 1 | J31: 55050 | K31: 0 | L31: 1 | M31: 是
A32: 32 | B32: HDMKLOGIC0316033 | C32: 分隔线首点在行政区划内检查 | D32: lgmap_lane_divider | E32: geometry | F32: A | G32: 0.9984 | H32: 工具 | I32: 1 | J32: 55050 | K32: 0 | L32: 1 | M32: 是
A33: 33 | B33: MKLOGIC1302007 | C33: 杆对象间距离过近检查 | D33: lgmap_object_line_pole | E33: geometry | F33: C | G33: 0.98 | H33: 工具 | I33: 1 | J33: 17737 | K33: 3 | L33: 0.99983086 | M33: 是
... A39: 39 | B39: HDMKLOGIC0309021 | C39: 高速连接匝道前继车道类型检查 | D39: lgmap_lane_divider | E39: category_location | F39: B | G39: 0.99 | H39: 工具 | I39: 1 | J39: 55050 | K39: 0 | L39: 1 | M39: 是
A40: 41 | B40: 20001 | C40: 几何检查：线的长度必须为正，且不能自相交；面的面积必须为正，且不能自相交。 | D40: lgmap_lane_divider | E40: geometry | F40: A | G40: 0.9984 | H40: 工具 | I40: 1 | J40: 55050 | K40: 0 | L40: 1 | M40: 是
A41: 42 | B41: HDMKLOGIC0309024 | C41: 加速车道前继车道类型检查 | D41: lgmap_lane_divider | E41: category_location | F41: B | G41: 0.99 | H41: 工具 | I41: 1 | J41: 55050 | K41: 0 | L41: 1 | M41: 是
A42: 43 | B42: 20012 | C42: 检查是否有两个junction相交 | D42: lgmap_junction | E42: geometry | F42: C | G42: 0.98 | H42: 工具 | I42: 1 | J42: 1872 | K42: 0 | L42: 1 | M42: 是
A43: 45 | B43: 20015 | C43: 检查物理隔离对象的几何关系 | D43: lgmap_object_physical_boundary | E43: geometry | F43: B | G43: 0.99 | H43: 工具 | I43: 1 | J43: 36039 | K43: 1 | L43: 0.99997225 | M43: 是
A44: 46 | B44: HDMKLOGIC0309023 | C44: 减速车道后继车道类型检查 | D44: lgmap_lane_divider | E44: category_location | F44: B | G44: 0.99 | H44: 工具 | I44: 1 | J44: 55050 | K44: 0 | L44: 1 | M44: 是
A45: 47 | B45: MKLOGIC2204026 | C45: 减速带与中心线的建立关系正确性检查 | D45: lgmap_overlap | E45: object_id | F45: B | G45: 0.99 | H45: 工具 | I45: 1 | J45: 194834 | K45: 14 | L45: 0.99992814 | M45: 是
...

Sheet 5.与现实世界一致性检查
A1: 序号 | B1: 图层 | C1: 字段名称 | D1: 错误子类 | E1: 重要等级 | F1: 质量标准 | G1: 求和项:总量 | H1: 求和项:错误数 | I1: 正确率 | J1: 是否合格
A2: 1 | B2: 车道分隔线表 | C2: 车道类型-所处位置 | D2: 车道分隔线表::车道类型-所处位置错误 | E2: B | F2: 0.99 | G2: 56887 | H2: 551 | I2: =1-H2/G2 -> 0.99031413 | J2: =IF(I2>=F2,"是","否") -> 是
A3: 2 | B3: 车道分隔线表 | C3: 车道类型-特殊属性 | D3: 车道分隔线表::车道类型-特殊属性错误 | E3: B | F3: 0.99 | G3: 56887 | H3: 1 | I3: =1-H3/G3 -> 0.99998242 | J3: =IF(I3>=F3,"是","否") -> 是
A4: 3 | B4: 车道分隔线表 | C4: 车道主类型 | D4: 车道分隔线表::车道主类型错误 | E4: B | F4: 0.99 | G4: 56887 | H4: 59 | I4: =1-H4/G4 -> 0.99896286 | J4: =IF(I4>=F4,"是","否") -> 是
A5: 4 | B5: 车道分隔线表 | C5: 分隔线附加属性 | D5: 车道分隔线表::分隔线附加属性错误 | E5: B | F5: 0.99 | G5: 56887 | H5: 98 | I5: =1-H5/G5 -> 0.99827729 | J5: =IF(I5>=F5,"是","否") -> 是
A6: 5 | B6: 车道分隔线表 | C6: 分隔线类型 | D6: 车道分隔线表::分隔线类型错误 | E6: B | F6: 0.99 | G6: 56887 | H6: 66 | I6: =1-H6/G6 -> 0.99883981 | J6: =IF(I6>=F6,"是","否") -> 是
A7: 6 | B7: 车道分隔线表 | C7: 分隔线颜色 | D7: 车道分隔线表::分隔线颜色错误 | E7: B | F7: 0.99 | G7: 56887 | H7: 48 | I7: =1-H7/G7 -> 0.99915622 | J7: =IF(I7>=F7,"是","否") -> 是
A8: 7 | B8: 车道分隔线表 | C8: 线坐标序列 | D8: 车道分隔线表::线坐标序列打断位置错误 | E8: A | F8: 0.9984 | G8: 56887 | H8: 54 | I8: =1-H8/G8 -> 0.99905075 | J8: =IF(I8>=F8,"是","否") -> 是
A9: 8 | B9: 车道分隔线表 | C9: 线坐标序列 | D9: 车道分隔线表::线坐标序列拓扑连接错误 | E9: A | F9: 0.9984 | G9: 56887 | H9: 4 | I9: =1-H9/G9 -> 0.99992969 | J9: =IF(I9>=F9,"是","否") -> 是
A10: 9 | B10: 车道分隔线表 | C10: 车道中线坐标序列 | D10: 车道分隔线表::线坐标序列位置精度错误 | E10: A | F10: 0.9984 | G10: 56887 | H10: 68 | I10: =1-H10/G10 -> 0.99880465 | J10: =IF(I10>=F10,"是","否") -> 是
A11: 10 | B11: 车道分隔线表 | C11: 线坐标序列 | D11: 车道分隔线表::线坐标序列遗漏 | E11: A | F11: 0.9984 | G11: 56887 | H11: 7 | I11: =1-H11/G11 -> 0.99987695 | J11: =IF(I11>=F11,"是","否") -> 是
A12: 11 | B12: 车道分隔线附加道路属性表 | C12: 道路形态 | D12: 车道分隔线附加道路属性表::道路形态错误 | E12: B | F12: 0.99 | G12: 14435 | H12: 10 | I12: =1-H12/G12 -> 0.99930724 | J12: =IF(I12>=F12,"是","否") -> 是
A13: 12 | B13: 车道中心线主表 | C13: 车道中线坐标序列 | D13: 车道中心线主表::车道中线坐标序列位置精度错误 | E13: A | F13: 0.9984 | G13: 40952 | H13: 3 | I13: =1-H13/G13 -> 0.99992674 | J13: =IF(I13>=F13,"是","否") -> 是
... A51: 51 | B51: 物理隔离对象表 | C51: 子类型 | D51: 物理隔离对象表::子类型错误 | E51: C | F51: 0.98 | G51: 36565 | H51: 25 | I51: =1-H51/G51 -> 0.99931629 | J51: =IF(I51>=F51,"是","否") -> 是
